<?xml version="1.0" ?>
<!-- =================================================================================== -->
<!-- |    This document was autogenerated by xacro from darci.urdf.xacro               | -->
<!-- |    EDITING THIS FILE BY HAND IS NOT RECOMMENDED                                 | -->
<!-- =================================================================================== -->
<robot name="Darci" xmlns:xacro="http://www.ros.org/wiki/xacro">
  <!-- simulator_gazebo plugins and tags for inclusion in sdf -->
  <gazebo refernce="darci">
    <material>Gazebo/Grey</material>
    <plugin filename="libros_model_plugin.so" name="ros_model_plugin"/>
    <static> false </static>
  </gazebo>
  <gazebo reference="right_arm_j0">
    <kp>1.0</kp>
    <kd>1.0</kd>
    <stopCfm>0.8</stopCfm>
    <stopErp>0.5</stopErp>
    <provideFeedback>true</provideFeedback>
    <cfmDamping>true</cfmDamping>
    <fudgeFactor>0.0</fudgeFactor>
  </gazebo>
  <gazebo reference="right_arm_j1">
    <kp>1.0</kp>
    <kd>1.0</kd>
    <stopCfm>0.8</stopCfm>
    <stopErp>0.5</stopErp>
    <provideFeedback>true</provideFeedback>
    <cfmDamping>true</cfmDamping>
    <fudgeFactor>0.0</fudgeFactor>
  </gazebo>
  <gazebo reference="right_arm_j2">
    <kp>1.0</kp>
    <kd>1.0</kd>
    <stopCfm>0.8</stopCfm>
    <stopErp>0.5</stopErp>
    <provideFeedback>true</provideFeedback>
    <cfmDamping>true</cfmDamping>
    <fudgeFactor>0.0</fudgeFactor>
  </gazebo>
  <gazebo reference="right_arm_j3">
    <kp>1.0</kp>
    <kd>1.0</kd>
    <stopCfm>0.8</stopCfm>
    <stopErp>0.5</stopErp>
    <provideFeedback>true</provideFeedback>
    <cfmDamping>true</cfmDamping>
    <fudgeFactor>0.0</fudgeFactor>
  </gazebo>
  <gazebo reference="right_arm_j4">
    <kp>1.0</kp>
    <kd>1.0</kd>
    <stopCfm>0.8</stopCfm>
    <stopErp>0.5</stopErp>
    <provideFeedback>true</provideFeedback>
    <cfmDamping>true</cfmDamping>
    <fudgeFactor>0.0</fudgeFactor>
  </gazebo>
  <gazebo reference="right_arm_j5">
    <kp>1.0</kp>
    <kd>1.0</kd>
    <stopCfm>0.8</stopCfm>
    <stopErp>0.5</stopErp>
    <provideFeedback>true</provideFeedback>
    <cfmDamping>true</cfmDamping>
    <fudgeFactor>0.0</fudgeFactor>
  </gazebo>
  <gazebo reference="right_arm_j6">
    <kp>1.0</kp>
    <kd>1.0</kd>
    <stopCfm>0.8</stopCfm>
    <stopErp>0.5</stopErp>
    <provideFeedback>true</provideFeedback>
    <cfmDamping>true</cfmDamping>
    <fudgeFactor>0.0</fudgeFactor>
  </gazebo>
  <gazebo reference="left_arm_j0">
    <kp>1.0</kp>
    <kd>1.0</kd>
    <stopCfm>0.8</stopCfm>
    <stopErp>0.5</stopErp>
    <provideFeedback>true</provideFeedback>
    <cfmDamping>true</cfmDamping>
    <fudgeFactor>0.0</fudgeFactor>
  </gazebo>
  <gazebo reference="left_arm_j1">
    <kp>1.0</kp>
    <kd>1.0</kd>
    <stopCfm>0.8</stopCfm>
    <stopErp>0.5</stopErp>
    <provideFeedback>true</provideFeedback>
    <cfmDamping>true</cfmDamping>
    <fudgeFactor>0.0</fudgeFactor>
  </gazebo>
  <gazebo reference="left_arm_j2">
    <kp>1.0</kp>
    <kd>1.0</kd>
    <stopCfm>0.8</stopCfm>
    <stopErp>0.5</stopErp>
    <provideFeedback>true</provideFeedback>
    <cfmDamping>true</cfmDamping>
    <fudgeFactor>0.0</fudgeFactor>
  </gazebo>
  <gazebo reference="left_arm_j3">
    <kp>1.0</kp>
    <kd>1.0</kd>
    <stopCfm>0.8</stopCfm>
    <stopErp>0.5</stopErp>
    <provideFeedback>true</provideFeedback>
    <cfmDamping>true</cfmDamping>
    <fudgeFactor>0.0</fudgeFactor>
  </gazebo>
  <gazebo reference="left_arm_j4">
    <kp>1.0</kp>
    <kd>1.0</kd>
    <stopCfm>0.8</stopCfm>
    <stopErp>0.5</stopErp>
    <provideFeedback>true</provideFeedback>
    <cfmDamping>true</cfmDamping>
    <fudgeFactor>0.0</fudgeFactor>
  </gazebo>
  <gazebo reference="left_arm_j5">
    <kp>1.0</kp>
    <kd>1.0</kd>
    <stopCfm>0.8</stopCfm>
    <stopErp>0.5</stopErp>
    <provideFeedback>true</provideFeedback>
    <cfmDamping>true</cfmDamping>
    <fudgeFactor>0.0</fudgeFactor>
  </gazebo>
  <gazebo reference="left_arm_j6">
    <kp>1.0</kp>
    <kd>1.0</kd>
    <stopCfm>0.8</stopCfm>
    <stopErp>0.5</stopErp>
    <provideFeedback>true</provideFeedback>
    <cfmDamping>true</cfmDamping>
    <fudgeFactor>0.0</fudgeFactor>
  </gazebo>
  <gazebo reference="shoulderupper_LEFT">
    <gravity>false</gravity>
    <mu1>0.01</mu1>
    <mu2>0.01</mu2>
  </gazebo>
  <gazebo reference="shoulderpitch_LEFT">
    <gravity>false</gravity>
    <mu1>0.01</mu1>
    <mu2>0.01</mu2>
  </gazebo>
  <gazebo reference="bicep_LEFT">
    <gravity>false</gravity>
    <mu1>0.01</mu1>
    <mu2>0.01</mu2>
  </gazebo>
  <gazebo reference="elbowclevis_LEFT">
    <gravity>false</gravity>
    <mu1>0.01</mu1>
    <mu2>0.01</mu2>
  </gazebo>
  <gazebo reference="wrist_LEFT">
    <gravity>false</gravity>
    <mu1>0.01</mu1>
    <mu2>0.01</mu2>
    <sensor name="wrist_LEFT_tactile_sensor" type="contact">
      <contact>
        <collision>wrist_LEFT_collision</collision>
        <topic>__default_topic__</topic>
      </contact>
      <plugin filename="libros_tactile_plugin.so" name="ros_tactile_plugin_wrist_LEFT"/>
      <always_on>1</always_on>
      <update_rate>30.0</update_rate>
      <visualize>false</visualize>
    </sensor>
  </gazebo>
  <gazebo reference="w_differential_LEFT">
    <gravity>false</gravity>
    <mu1>0.01</mu1>
    <mu2>0.01</mu2>
  </gazebo>
  <gazebo reference="handmount_LEFT">
    <gravity>false</gravity>
    <mu1>0.01</mu1>
    <mu2>0.01</mu2>
    <sensor name="handmount_LEFT_tactile_sensor" type="contact">
      <contact>
        <collision>handmount_LEFT_collision</collision>
        <topic>__default_topic__</topic>
      </contact>
      <plugin filename="libros_tactile_plugin.so" name="ros_tactile_plugin_handmount_LEFT"/>
      <always_on>1</always_on>
      <update_rate>30.0</update_rate>
      <visualize>false</visualize>
    </sensor>
  </gazebo>
  <gazebo reference="handmount_FT_LEFT">
    <gravity>false</gravity>
    <mu1>0.01</mu1>
    <mu2>0.01</mu2>
  </gazebo>
  <gazebo reference="flipper">
    <gravity>false</gravity>
    <mu1>0.01</mu1>
    <mu2>0.01</mu2>
  </gazebo>
  <gazebo reference="shoulderupper_RIGHT">
    <gravity>false</gravity>
    <mu1>0.01</mu1>
    <mu2>0.01</mu2>
  </gazebo>
  <gazebo reference="shoulderpitch_RIGHT">
    <gravity>false</gravity>
    <mu1>0.01</mu1>
    <mu2>0.01</mu2>
  </gazebo>
  <gazebo reference="bicep_RIGHT">
    <gravity>false</gravity>
    <mu1>0.01</mu1>
    <mu2>0.01</mu2>
  </gazebo>
  <gazebo reference="elbowclevis_RIGHT">
    <gravity>false</gravity>
    <mu1>0.01</mu1>
    <mu2>0.01</mu2>
  </gazebo>
  <gazebo reference="wrist_RIGHT">
    <gravity>false</gravity>
    <mu1>0.01</mu1>
    <mu2>0.01</mu2>
  </gazebo>
  <gazebo reference="w_differential_RIGHT">
    <gravity>false</gravity>
    <mu1>0.01</mu1>
    <mu2>0.01</mu2>
  </gazebo>
  <gazebo reference="handmount_RIGHT">
    <gravity>false</gravity>
    <mu1>0.01</mu1>
    <mu2>0.01</mu2>
  </gazebo>
  <!-- Meka Base -->
  <!-- Meka Zlift -->
  <!-- Meka Arm -->
  <!-- HRL End Effector -->
  <!-- john added transmissions -->
  <link name="world"/>
  <joint name="X" type="fixed">
    <axis xyz="1 0 0"/>
    <origin rpy="0 0 0" xyz="0.0 0.0 0.02"/>
    <parent link="world"/>
    <child link="dummy_1"/>
    <limit effort="30" lower="-0.714601836603" upper="2.2853981634" velocity="3.48"/>
    <dynamics damping="10.0"/>
    <safety_controller k_position="100" k_velocity="10" soft_lower_limit="-0.564601836603" soft_upper_limit="2.1353981634"/>
  </joint>
  <link name="dummy_1">
    <inertial>
      <mass value="0.1"/>
      <origin rpy="0 0 0" xyz="0.0 0.0 0.3"/>
      <inertia ixx="0.01" ixy="-0.006086507933" ixz="-0.0012118061183" iyy="0.01" iyz="-0.005886609911" izz="0.01"/>
    </inertial>
  </link>
  <joint name="Y" type="fixed">
    <axis xyz="0 1 0"/>
    <limit effort="30" lower="-0.5236" upper="1.3963" velocity="3.47"/>
    <safety_controller k_position="100" k_velocity="10" soft_lower_limit="-0.3536" soft_upper_limit="1.3463"/>
    <dynamics damping="10.0"/>
    <origin rpy="0 0 0" xyz="0 0 0"/>
    <parent link="dummy_1"/>
    <child link="dummy_2"/>
  </joint>
  <link name="dummy_2">
    <inertial>
      <mass value="0.1"/>
      <origin rpy="0 0 0" xyz="0.0 0.0 0.0"/>
      <inertia ixx="0.02105584615" ixy="0.00496704022" ixz="-0.00194808955" iyy="0.02127223737" iyz="0.00110425490" izz="0.01975753814"/>
    </inertial>
  </link>
  <joint name="yaw" type="fixed">
    <axis xyz="0 0 1"/>
    <origin rpy="0 0 0" xyz="0 0.0 0.0"/>
    <parent link="dummy_2"/>
    <child link="dummy_3"/>
    <limit effort="30" lower="-0.8" upper="3.9" velocity="5.45"/>
    <safety_controller k_position="100" k_velocity="2" soft_lower_limit="-0.65" soft_upper_limit="3.75"/>
    <dynamics damping="0.1"/>
  </joint>
  <link name="dummy_3">
    <inertial>
      <!-- these mass/inertial values are very rough guess-timates -->
      <mass value="100"/>
      <origin xyz="-0.07 0 0.25"/>
      <inertia ixx="7.0" ixy="1" ixz="0.1" iyy="6.66" iyz="0.1" izz="2.6"/>
    </inertial>
    <visual>
      <origin rpy="0 0 0" xyz="0 0 0"/>
      <geometry name="b1r1_3_geom">
        <mesh filename="meshes/mid_res/B1R1/MB1_00_000_meka_mobile_base+backpack+zlift.dae"/>
      </geometry>
    </visual>
    <collision>
      <origin rpy="0.0 0.0 0.0 " xyz="0 0 0"/>
      <geometry name="b1r1_3_geom">
        <mesh filename="meshes/low_res/B1R1/MB1_00_000_meka_mobile_base+backpack+zlift.stl"/>
      </geometry>
    </collision>
  </link>
  <joint name="torso_lift_joint" type="prismatic">
    <axis xyz="0 0 1"/>
    <origin rpy="0 0 0" xyz="0.42 0.0 0.6137"/>
    <parent link="dummy_3"/>
    <child link="torso_lift_link"/>
    <!-- torso_lift limit values are purely invented -->
    <limit effort="2000.0" lower="0.0" upper="0.7" velocity="0.2"/>
    <dynamics damping="100.0"/>
  </joint>
  <link name="torso_lift_link">
    <inertial>
      <mass value="5.799322"/>
      <origin rpy="0 0 0" xyz="0.0 0.0 -0.10"/>
      <inertia ixx="0.206179142480" ixy="-0.006086507933" ixz="-0.01118061183" iyy="0.20421714893" iyz="-0.005886609911" izz="0.05353821674"/>
    </inertial>
    <visual>
      <origin rpy="0 0 0 " xyz="0 0 -0.1937"/>
      <geometry name="torso_lift_geom">
        <mesh filename="meshes/mid_res/B1R1/MB1_00_011_festo-chest_mount_assy+spacer.dae"/>
      </geometry>
    </visual>
    <collision>
      <origin rpy="0.0 0.0 0.0 " xyz="0 0 -0.1937"/>
      <geometry name="torso_lift_geom_collision_geom">
        <mesh filename="meshes/low_res/B1R1/MB1_00_011_festo-chest_mount_assy+spacer.stl"/>
      </geometry>
    </collision>
  </link>
  <!-- Torso -->
  <joint name="chest_joint" type="fixed">
    <origin xyz="0.0 0.0 0.0"/>
    <parent link="torso_lift_link"/>
    <child link="chest_link"/>
  </joint>
  <link name="chest_link">
    <inertial>
      <mass value="10"/>
      <origin xyz="0 0 -0.1"/>
      <inertia ixx="1E-4" ixy="1E-7" ixz="1E-7" iyy="1E-4" iyz="1E-7" izz="1E-4"/>
    </inertial>
    <visual>
      <origin rpy="0 0 0" xyz="0 0 -0.2337"/>
      <geometry name="torso_lift_link_geom">
        <mesh filename="meshes/mid_res/A2R3/A2R3_T4_Chest_Neck.dae"/>
      </geometry>
    </visual>
    <collision>
      <origin rpy="0.0 0.0 0.0 " xyz="0 0 -0.2337"/>
      <geometry name="torso_lift_link_collision_geom">
        <mesh filename="meshes/low_res/A2R3/A2R3_T4_Chest_Neck.stl"/>
      </geometry>
    </collision>
  </link>
  <!-- Add Arms -->
  <joint name="right_arm_j0" type="revolute">
    <axis xyz="0 -1 0"/>
    <origin rpy="0.0 0.0 0.0" xyz="0.0 -0.18465 0."/>
    <!-- transform from parent link to this joint frame -->
    <parent link="torso_lift_link"/>
    <child link="shoulderupper_RIGHT"/>
    <limit effort="40" lower="-1.3962634016" upper="3.49065850399" velocity="4.6"/>
    <dynamics damping="10.0"/>
  </joint>
  <link name="shoulderupper_RIGHT">
    <inertial>
      <mass value="1.9872"/>
      <origin xyz="-0.00936788 0.02395458 -2.088E-5"/>
      <inertia ixx="0.00356693" ixy="0.00037871" ixz="-2.58E-6" iyy="0.00293851" iyz="2.2E-7" izz="0.00527258"/>
    </inertial>
    <visual>
      <origin xyz="0 0 0"/>
      <geometry name="r_shoulder_geom">
        <mesh filename="meshes/mid_res/A2R3/A2R3_RT1_shoulderRoll.dae"/>
      </geometry>
    </visual>
    <collision name="shoulderupper_RIGHT_collision">
      <origin rpy="0.0 0.0 0.0 " xyz="0 0 0"/>
      <geometry name="r_shoulder_collision_geom">
        <mesh filename="meshes/low_res/A2R3/A2R3_RT1_shoulderRoll.stl"/>
      </geometry>
    </collision>
  </link>
  <joint name="right_arm_j1" type="revolute">
    <axis xyz="-1 0 0"/>
    <limit effort="40" lower="-0.436332312999" upper="2.61799387799" velocity="4.6"/>
    <origin rpy="0 0 0" xyz="0 0 0"/>
    <parent link="shoulderupper_RIGHT"/>
    <child link="shoulderpitch_RIGHT"/>
    <dynamics damping="10.0"/>
  </joint>
  <link name="shoulderpitch_RIGHT">
    <inertial>
      <mass value="0.5575"/>
      <origin rpy="0 0 0" xyz="0.00080377 -0.02635544 -0.0430649"/>
      <inertia ixx="0.00074973" ixy="0.00001619" ixz="0.00001457" iyy="0.00091716" iyz="0.00014161" izz="0.00083106"/>
    </inertial>
    <visual>
      <origin rpy="0 0 0 " xyz="0 0 0"/>
      <geometry name="shoulderpitch_RIGHT">
        <mesh filename="meshes/mid_res/A2R3/A2R3_RT2_shoulderPitch.dae"/>
      </geometry>
    </visual>
    <collision name="shoulderpitch_RIGHT_collision">
      <origin rpy="0.0 0.0 0.0 " xyz="0 0 0"/>
      <geometry name="shoulderpitch_RIGHT__geom_collision">
        <mesh filename="meshes/low_res/A2R3/A2R3_RT2_shoulderPitch.stl"/>
      </geometry>
    </collision>
  </link>
  <joint name="right_arm_j2" type="revolute">
    <axis xyz="0 0 -1"/>
    <origin rpy="0 0 0" xyz="0 -0.03175 -0.27857"/>
    <parent link="shoulderpitch_RIGHT"/>
    <child link="bicep_RIGHT"/>
    <limit effort="20" lower="-1.4835298642" upper="1.4835298642" velocity="4.5"/>
    <dynamics damping="10.0"/>
  </joint>
  <link name="bicep_RIGHT">
    <inertial>
      <mass value="2.22"/>
      <origin rpy="0 0 0" xyz="-0.00802582 1.816E-5 0.08769598"/>
      <inertia ixx="0.01204788" ixy="-0.00007315" ixz="-0.00057377" iyy="0.01227149" iyz="-0.00012629" izz="0.0021075"/>
    </inertial>
    <visual>
      <origin rpy="0 0 0 " xyz="0 0 0"/>
      <geometry name="bicep_RIGHT_geom">
        <mesh filename="meshes/mid_res/A2R3/A2R3_RT3_bicep.dae"/>
      </geometry>
    </visual>
    <collision name="bicep_RIGHT_collision">
      <origin rpy="0.0 0.0 0.0 " xyz="0 0 0"/>
      <geometry name="bicep_RIGHT_geom_collision">
        <mesh filename="meshes/low_res/A2R3/A2R3_RT3_bicep.stl"/>
      </geometry>
    </collision>
  </link>
  <joint name="right_arm_j3" type="revolute">
    <axis xyz="0 -1 0"/>
    <origin rpy="0 0 0" xyz="0.00502 0  0"/>
    <parent link="bicep_RIGHT"/>
    <child link="elbowclevis_RIGHT"/>
    <limit effort="20" lower="0.0" upper="2.32128790515" velocity="4.5"/>
    <dynamics damping="5.0"/>
  </joint>
  <link name="elbowclevis_RIGHT">
    <inertial>
      <mass value="0.22"/>
      <origin xyz="0.0 0.00080947 -0.02573092 "/>
      <inertia ixx="0.00046386" ixy="0.0" ixz="0.0" iyy="0.00023071" iyz="0.00001793" izz="0.00041935"/>
    </inertial>
    <visual>
      <origin rpy="0 0 0 " xyz="0 0 0"/>
      <geometry name="elbowclevis_RIGHT_geom">
        <mesh filename="meshes/mid_res/A2R3/A2R3_RT4_elbow.dae"/>
      </geometry>
    </visual>
    <collision name="elbowclevis_RIGHT_collision">
      <origin rpy="0.0 0.0 0.0 " xyz="0 0 0"/>
      <geometry name="elbowclevis_RIGHT_geom_collision">
        <mesh filename="meshes/low_res/A2R3/A2R3_RT4_elbow.stl"/>
      </geometry>
    </collision>
  </link>
  <joint name="right_arm_j4" type="revolute">
    <axis xyz="0 0 -1"/>
    <limit effort="4" lower="-0.349065850399" upper="3.40339204139" velocity="2.0"/>
    <origin rpy="0 0 0" xyz="0 0 -0.27747"/>
    <parent link="elbowclevis_RIGHT"/>
    <child link="wrist_RIGHT"/>
    <dynamics damping="2.0"/>
  </joint>
  <link name="wrist_RIGHT">
    <inertial>
      <mass value="1.7"/>
      <origin xyz="-0.00193729 -0.00046171 0.13853286"/>
      <inertia ixx="0.00637623" ixy="0.00000157" ixz="-0.00000634" iyy="0.00632479" iyz="0.00000499" izz="0.00106567"/>
    </inertial>
    <visual>
      <origin rpy="0 0 0 " xyz="0 0 0"/>
      <geometry name="wrist_RIGHT_geom">
        <mesh filename="meshes/mid_res/A2R3/A2R3_T5_forearmRoll.dae"/>
      </geometry>
    </visual>
    <collision name="wrist_RIGHT_collision">
      <origin rpy="0.0 0.0 0.0 " xyz="0 0 0"/>
      <geometry name="wrist_RIGHT_geom_collision">
        <mesh filename="meshes/low_res/A2R3/A2R3_T5_forearmRoll.stl"/>
      </geometry>
    </collision>
  </link>
  <joint name="right_arm_j5" type="revolute">
    <axis xyz="0 -1 0"/>
    <origin rpy="0 0 0" xyz="0 0 0"/>
    <parent link="wrist_RIGHT"/>
    <child link="w_differential_RIGHT"/>
    <limit effort="8" lower="-1.0471975512" upper="1.0471975512" velocity="3.4"/>
    <dynamics damping="1.0"/>
  </joint>
  <link name="w_differential_RIGHT">
    <inertial>
      <mass value="0.212"/>
      <origin xyz="-0.00183795 -0.0018201 -8.772E-5"/>
      <inertia ixx="0.0001092" ixy="0.00000081" ixz="0.00000007" iyy="0.00007173" iyz="0.00000004" izz="0.00011046"/>
    </inertial>
    <visual>
      <origin rpy="0 0 0 " xyz="0 0 0"/>
      <geometry name="w_differential_RIGHT_geom">
        <mesh filename="meshes/mid_res/A2R3/A2R3_T6_wristDiff.dae"/>
      </geometry>
    </visual>
    <collision name="w_differential_RIGHT_collision">
      <origin rpy="0.0 0.0 0.0 " xyz="0 0 0"/>
      <geometry name="w_differential_RIGHT_geom_collision">
        <box size="0.01 0.01 0.01"/>
      </geometry>
    </collision>
  </link>
  <joint name="right_arm_j6" type="revolute">
    <axis xyz="-1 0 0"/>
    <limit effort="8" lower="-1.0471975512" upper="1.0471975512" velocity="3.4"/>
    <origin rpy="0 0 0" xyz="0 0 0"/>
    <parent link="w_differential_RIGHT"/>
    <child link="handmount_RIGHT"/>
    <dynamics damping="1.0"/>
  </joint>
  <link name="handmount_RIGHT">
    <inertial>
      <mass value="0.084"/>
      <origin xyz="-0.00292 3.0E-5 -0.01092"/>
      <inertia ixx="4.30537E-5" ixy="-4.351E-8" ixz="-1.49262E-6" iyy="8.64045E-5" iyz="8.517E-8" izz="6.14459E-5"/>
    </inertial>
    <visual>
      <origin rpy="0 0 0 " xyz="0 0 0"/>
      <geometry name="handmount_RIGHT_geom">
        <mesh filename="meshes/mid_res/A2R3/A2R3_T7_wristYaw.dae"/>
      </geometry>
    </visual>
    <collision name="handmount_RIGHT_collision">
      <origin rpy="0.0 0.0 0.0 " xyz="0 0 0"/>
      <geometry name="handmount_RIGHT__geom_collision">
        <mesh filename="meshes/low_res/A2R3/A2R3_T7_wristYaw.stl"/>
      </geometry>
    </collision>
  </link>
  <joint name="left_arm_j0" type="revolute">
    <axis xyz="0 -1 0"/>
    <origin rpy="0.0 0.0 0.0" xyz="0.0 0.18465 0."/>
    <!-- transform from parent link to this joint frame -->
    <parent link="torso_lift_link"/>
    <child link="shoulderupper_LEFT"/>
    <limit effort="40" lower="-1.3962634016" upper="3.49065850399" velocity="4.6"/>
    <dynamics damping="10.0"/>
  </joint>
  <link name="shoulderupper_LEFT">
    <inertial>
      <mass value="1.9872"/>
      <origin xyz="-0.00936788 -0.02395458 -2.088E-5"/>
      <inertia ixx="0.00356692" ixy="-0.00036869" ixz="-0.00000245" iyy="0.00293838" iyz="0.00000097" izz="0.00527243"/>
    </inertial>
    <visual>
      <origin rpy="3.14159265359 0 0" xyz="0 0 0"/>
      <geometry name="l_shoulder_geom">
        <mesh filename="meshes/mid_res/A2R3/A2R3_RT1_shoulderRoll.dae"/>
      </geometry>
    </visual>
    <collision name="shoulderupper_LEFT_collision">
      <origin rpy="3.14159265359 0 0" xyz="0 0 0"/>
      <geometry name="l_shoulder_collision_geom">
        <mesh filename="meshes/low_res/A2R3/A2R3_RT1_shoulderRoll.stl"/>
      </geometry>
    </collision>
  </link>
  <joint name="left_arm_j1" type="revolute">
    <axis xyz="-1 0 0"/>
    <limit effort="40" lower="-2.61799387799" upper="0.436332312999" velocity="4.6"/>
    <origin rpy="0 0 0" xyz="0 0 0"/>
    <parent link="shoulderupper_LEFT"/>
    <child link="shoulderpitch_LEFT"/>
    <dynamics damping="10.0"/>
  </joint>
  <link name="shoulderpitch_LEFT">
    <inertial>
      <mass value="0.5575"/>
      <origin rpy="0 0 0" xyz="0.00102576 0.02635544 -0.0430649"/>
      <inertia ixx="0.00074999" ixy="-0.00001075" ixz="0.00002945" iyy="0.00091729" iyz="-0.0001417" izz="0.00083104"/>
    </inertial>
    <visual>
      <origin rpy="0 0 3.14159265359" xyz="0 0 0"/>
      <geometry name="l_shoulderpitch_RIGHT">
        <mesh filename="meshes/mid_res/A2R3/A2R3_RT2_shoulderPitch.dae"/>
      </geometry>
    </visual>
    <collision name="shoulderpitch_LEFT_collision">
      <origin rpy="0.0 0.0 3.14159265359" xyz="0 0 0"/>
      <geometry name="shoulderpitch_LEFT_geom_collision">
        <mesh filename="meshes/low_res/A2R3/A2R3_RT2_shoulderPitch.stl"/>
      </geometry>
    </collision>
  </link>
  <joint name="left_arm_j2" type="revolute">
    <axis xyz="0 0 -1"/>
    <origin rpy="0 0 0" xyz="0 0.03175 -0.27857"/>
    <parent link="shoulderpitch_LEFT"/>
    <child link="bicep_LEFT"/>
    <limit effort="20" lower="-1.4835298642" upper="1.4835298642" velocity="4.5"/>
    <dynamics damping="10.0"/>
  </joint>
  <link name="bicep_LEFT">
    <inertial>
      <mass value="2.22"/>
      <origin rpy="0 0 0" xyz="-0.008000832 -0.00267341 0.08765621"/>
      <inertia ixx="0.01203537" ixy="0.00003201" ixz="-0.00057519" iyy="0.01227275" iyz="0.00007938" izz="0.00209411"/>
    </inertial>
    <visual>
      <origin rpy="0 0 0 " xyz="0 0 0"/>
      <geometry name="bicep_LEFT_geom">
        <mesh filename="meshes/mid_res/A2R3/A2R3_LT3_bicep.dae"/>
      </geometry>
    </visual>
    <collision name="bicep_LEFT_collision">
      <origin rpy="0.0 0.0 0.0 " xyz="0 0 0"/>
      <geometry name="bicep_LEFT_geom_collision">
        <mesh filename="meshes/low_res/A2R3/A2R3_LT3_bicep.stl"/>
      </geometry>
    </collision>
  </link>
  <joint name="left_arm_j3" type="revolute">
    <axis xyz="0 -1 0"/>
    <origin rpy="0 0 0" xyz="0.00502 0  0"/>
    <parent link="bicep_LEFT"/>
    <child link="elbowclevis_LEFT"/>
    <limit effort="20" lower="0.0" upper="2.32128790515" velocity="4.5"/>
    <dynamics damping="5.0"/>
  </joint>
  <link name="elbowclevis_LEFT">
    <inertial>
      <mass value="0.22"/>
      <origin xyz="0.0 -0.00080947 -0.02573092 "/>
      <inertia ixx="0.00046386" ixy="0.0" ixz="0.0" iyy="0.00023071" iyz="-0.00001793" izz="0.00041935"/>
    </inertial>
    <visual>
      <origin rpy="0 0 3.14159265359 " xyz="0 0 0"/>
      <geometry name="elbowclevis_LEFT_geom">
        <mesh filename="meshes/mid_res/A2R3/A2R3_RT4_elbow.dae"/>
      </geometry>
    </visual>
    <collision name="elbowclevis_LEFT_collision">
      <origin rpy="0.0 0.0 3.14159265359 " xyz="0 0 0"/>
      <geometry name="elbowclevis_LEFT_geom_collision">
        <mesh filename="meshes/low_res/A2R3/A2R3_RT4_elbow.stl"/>
      </geometry>
    </collision>
  </link>
  <joint name="left_arm_j4" type="revolute">
    <axis xyz="0 0 -1"/>
    <limit effort="4" lower="-3.32834288355" upper="0.436332312999" velocity="2.0"/>
    <origin rpy="0 0 0" xyz="0 0 -0.27747"/>
    <parent link="elbowclevis_LEFT"/>
    <child link="wrist_LEFT"/>
    <dynamics damping="2.0"/>
  </joint>
  <link name="wrist_LEFT">
    <inertial>
      <mass value="1.7"/>
      <origin xyz="-0.00193731 -0.0002874 0.13853286"/>
      <inertia ixx="0.00637642" ixy="-0.00000052" ixz="0.00000634" iyy="0.00632479" iyz="-0.00006565" izz="0.00106585"/>
    </inertial>
    <visual>
      <origin rpy="0 0 0 " xyz="0 0 0"/>
      <geometry name="wrist_LEFT_geom">
        <mesh filename="meshes/mid_res/A2R3/A2R3_T5_forearmRoll.dae"/>
      </geometry>
    </visual>
    <collision name="wrist_LEFT_collision">
      <origin rpy="0.0 0.0 0.0 " xyz="0 0 0"/>
      <geometry name="wrist_LEFT_geom_collision">
        <mesh filename="meshes/low_res/A2R3/A2R3_T5_forearmRoll.stl"/>
        <!--mesh filename="package://${MESH_COLL}/A2R3/A2R3_T5_forearmRoll_coll.stl"/ -->
      </geometry>
    </collision>
  </link>
  <joint name="left_arm_j5" type="revolute">
    <axis xyz="0 -1 0"/>
    <origin rpy="0 0 0" xyz="0 0 0"/>
    <parent link="wrist_LEFT"/>
    <child link="w_differential_LEFT"/>
    <limit effort="8" lower="-1.0471975512" upper="1.0471975512" velocity="3.4"/>
    <dynamics damping="1.0"/>
  </joint>
  <link name="w_differential_LEFT">
    <inertial>
      <mass value="0.212"/>
      <origin xyz="-0.00183795 0.0018201 -8.772E-5"/>
      <inertia ixx="0.0001092" ixy="0.00000081" ixz="0.00000007" iyy="0.00007173" iyz="0.00000004" izz="0.00011046"/>
    </inertial>
    <visual>
      <origin rpy="0 0 0 " xyz="0 0 0"/>
      <geometry name="w_differential_LEFT_geom">
        <mesh filename="meshes/mid_res/A2R3/A2R3_T6_wristDiff.dae"/>
      </geometry>
    </visual>
    <collision name="w_differential_LEFT_collision">
      <origin rpy="0.0 0.0 0.0 " xyz="0 0 0"/>
      <geometry name="w_differential_LEFT_geom_collision">
        <box size="0.01 0.01 0.01"/>
      </geometry>
    </collision>
  </link>
  <joint name="left_arm_j6" type="revolute">
    <axis xyz="-1 0 0"/>
    <limit effort="8" lower="-1.0471975512" upper="1.0471975512" velocity="3.4"/>
    <origin rpy="0 0 0" xyz="0 0 0"/>
    <parent link="w_differential_LEFT"/>
    <child link="handmount_LEFT"/>
    <dynamics damping="1.0"/>
  </joint>
  <link name="handmount_LEFT">
    <inertial>
      <mass value="0.084"/>
      <origin xyz="-0.00292 -3.0E-5 -0.01092"/>
      <inertia ixx="4.30537E-5" ixy="-4.351E-8" ixz="-1.49262E-8" iyy="8.64045E-5" iyz="8.517E-8" izz="6.14459E-5"/>
    </inertial>
    <visual>
      <origin rpy="0 0 0 " xyz="0 0 0"/>
      <geometry name="handmount_LEFT_geom">
        <mesh filename="meshes/mid_res/A2R3/A2R3_T7_wristYaw.dae"/>
      </geometry>
    </visual>
    <collision name="handmount_LEFT_collision">
      <origin rpy="0.0 0.0 0.0 " xyz="0 0 0"/>
      <geometry name="handmount_LEFT_geom_collision">
        <mesh filename="meshes/low_res/A2R3/A2R3_T7_wristYaw.stl"/>
        <!--mesh filename="package://${MESH_COLL}/tactile_sensor/new_handmount_LEFT.stl"  scale="0.001 0.001 0.001"/-->
      </geometry>
    </collision>
  </link>
  <joint name="handmount_ft_joint" type="fixed">
    <origin rpy="0 0 0" xyz="0.0 0.0 -0.05125"/>
    <!-- transform from parent link to this joint frame -->
    <parent link="handmount_LEFT"/>
    <!--  <origin xyz="0.0 0.0 -0.05125" rpy="0 0 0" />
      <parent link="handmount_LEFT"/>-->
    <child link="handmount_FT_LEFT"/>
  </joint>
  <link name="handmount_FT_LEFT">
    <!-- values from data spec for ATI Mini40 sensor (read: should be fairly accurate)-->
    <inertial>
      <origin xyz="0.0 0.0 0.0"/>
      <mass value="0.0499"/>
      <inertia ixx="3.3838E-6" ixy="0" ixz="0" iyy="3.3838E-6" iyz="0" izz="1E-7"/>
    </inertial>
    <visual>
      <origin rpy="0 0 0 " xyz="0 0 0.0"/>
      <geometry>
        <cylinder length="0.0125" radius="0.02"/>
      </geometry>
    </visual>
    <!--collision>
	    <origin xyz="0 0 0.0" rpy="0 0 0 " />
        <geometry>
            <cylinder radius="0.02" length="0.0125" />
        </geometry>
      </collision-->
  </link>
  <joint name="handmount_flipper_joint" type="fixed">
    <origin rpy="-1.57079632679 0 -1.57079632679" xyz="0.0 0.0 0.0"/>
    <parent link="handmount_FT_LEFT"/>
    <child link="flipper"/>
  </joint>
  <link name="flipper">
    <inertial>
      <origin xyz="0.0 0.07 0.0"/>
      <mass value="0.18"/>
      <inertia ixx="0.00033755" ixy="0" ixz="0" iyy="0.00033755" iyz="0" izz="0.0001202"/>
    </inertial>
    <visual>
      <origin rpy="0 0 0 " xyz="0 0 0"/>
      <geometry name="flipper_geom">
        <mesh filename="meshes/mid_res/tactile_sensor/ee_simple.STL" scale="0.0009 0.00078 0.00085"/>
      </geometry>
      <material name="white">
        <color rgba="1 1 1 1"/>
      </material>
    </visual>
    <!--collision name="flipper_collision">
        <origin rpy="0.0 0.0 0.0 " xyz="0 0 0"/>
        <geometry name="flipper_geom_collision">
          <mesh filename="package://${MESH_COLL}/tactile_sensor/ee_simple.STL" scale="0.0009 0.00078 0.0009"/>
        </geometry>
      </collision-->
  </link>
  <joint name="left_arm_ee" type="fixed">
    <origin rpy="-1.570796 0 0" xyz="0 0 -0.17"/>
    <!--origin xyz="0 0 -0.19" rpy="-1.570796 0 0" /-->
    <parent link="handmount_LEFT"/>
    <child link="end_effector_LEFT"/>
  </joint>
  <link name="end_effector_LEFT">
    <!--inertial>
          <mass value="0.093" />
          <origin xyz="0 0 0" />
          <inertia ixx="0.0" ixy="0.0" ixz="0.0"
                   iyy="0.0" iyz="-0.0"
                   izz="0.0" />
          </inertial-->
    <visual>
      <geometry>
        <cylinder length="0.01" radius="0.001"/>
      </geometry>
      <material name="white">
        <color rgba="1 1 1 1"/>
      </material>
    </visual>
  </link>
  <!-- john added transmissions -->
  <transmission name="torso_lift_t0" type="pr2_mechanism_model/SimpleTransmission">
    <actuator name="torso_lift_a0"/>
    <joint name="torso_lift_joint"/>
    <mechanicalReduction>1</mechanicalReduction>
  </transmission>
  <transmission name="right_arm_t0" type="pr2_mechanism_model/SimpleTransmission">
    <actuator name="right_arm_a0"/>
    <joint name="right_arm_j0"/>
    <mechanicalReduction>1.0</mechanicalReduction>
  </transmission>
  <transmission name="right_arm_t1" type="pr2_mechanism_model/SimpleTransmission">
    <actuator name="right_arm_a1"/>
    <joint name="right_arm_j1"/>
    <mechanicalReduction>1.0</mechanicalReduction>
  </transmission>
  <transmission name="right_arm_t2" type="pr2_mechanism_model/SimpleTransmission">
    <actuator name="right_arm_a2"/>
    <joint name="right_arm_j2"/>
    <mechanicalReduction>1.0</mechanicalReduction>
  </transmission>
  <transmission name="right_arm_t3" type="pr2_mechanism_model/SimpleTransmission">
    <actuator name="right_arm_a3"/>
    <joint name="right_arm_j3"/>
    <mechanicalReduction>1.0</mechanicalReduction>
  </transmission>
  <transmission name="right_arm_t4" type="pr2_mechanism_model/SimpleTransmission">
    <actuator name="right_arm_a4"/>
    <joint name="right_arm_j4"/>
    <mechanicalReduction>1.0</mechanicalReduction>
  </transmission>
  <transmission name="right_arm_t5" type="pr2_mechanism_model/SimpleTransmission">
    <actuator name="right_arm_a5"/>
    <joint name="right_arm_j5"/>
    <mechanicalReduction>1.0</mechanicalReduction>
  </transmission>
  <transmission name="right_arm_t6" type="pr2_mechanism_model/SimpleTransmission">
    <actuator name="right_arm_a6"/>
    <joint name="right_arm_j6"/>
    <mechanicalReduction>1.0</mechanicalReduction>
  </transmission>
  <transmission name="left_arm_t0" type="pr2_mechanism_model/SimpleTransmission">
    <actuator name="left_arm_a0"/>
    <joint name="left_arm_j0"/>
    <mechanicalReduction>1.0</mechanicalReduction>
  </transmission>
  <transmission name="left_arm_t1" type="pr2_mechanism_model/SimpleTransmission">
    <actuator name="left_arm_a1"/>
    <joint name="left_arm_j1"/>
    <mechanicalReduction>1.0</mechanicalReduction>
  </transmission>
  <transmission name="left_arm_t2" type="pr2_mechanism_model/SimpleTransmission">
    <actuator name="left_arm_a2"/>
    <joint name="left_arm_j2"/>
    <mechanicalReduction>1.0</mechanicalReduction>
  </transmission>
  <transmission name="left_arm_t3" type="pr2_mechanism_model/SimpleTransmission">
    <actuator name="left_arm_a3"/>
    <joint name="left_arm_j3"/>
    <mechanicalReduction>1.0</mechanicalReduction>
  </transmission>
  <transmission name="left_arm_t4" type="pr2_mechanism_model/SimpleTransmission">
    <actuator name="left_arm_a4"/>
    <joint name="left_arm_j4"/>
    <mechanicalReduction>1.0</mechanicalReduction>
  </transmission>
  <transmission name="left_arm_t5" type="pr2_mechanism_model/SimpleTransmission">
    <actuator name="left_arm_a5"/>
    <joint name="left_arm_j5"/>
    <mechanicalReduction>1.0</mechanicalReduction>
  </transmission>
  <transmission name="left_arm_t6" type="pr2_mechanism_model/SimpleTransmission">
    <actuator name="left_arm_a6"/>
    <joint name="left_arm_j6"/>
    <mechanicalReduction>1.0</mechanicalReduction>
  </transmission>
</robot>
